Workbook
Name Slicer_Agent: #N/A
Name Slicer_Date__Month: #N/A

Sheet Instructions
B2: NovaTech Electronics — Customer Satisfaction KPI Training File
B3: A practice dataset for learning the 6 core Customer Satisfaction KPIs
B5: About this file
B6: This workbook contains realistic (but fictional) data for NovaTech Electronics, an online consumer electronics retailer. It mimics real customer support and sales operations data so students can practice calculating the customer satisfaction KPIs described in SupportYourApp's guide: Customer Satisfaction Score (CSAT), Net Promoter Score (NPS), Customer Effort Score (CES), Customer Churn Rate, First Contact Resolution (FCR), and Customer Lifetime Value (CLV).
B8: How the workbook is organized
B9: Instructions | C9: This sheet. Overview + KPI formula reference.
B10: Support_Tickets | C10: 480 raw support tickets (Jan–Jun 2026): channel, agent, issue type, first-contact resolution, resolution time, CSAT score (1–5), CES score (1–7).
B11: NPS_Survey | C11: 290 quarterly relationship survey responses (0–10 recommend score) used to calculate NPS.
B12: Customer_Accounts | C12: 260 customer accounts with signup date, segment, purchase history, and churn status — used for Churn Rate and CLV.
B13: KPI_Dashboard | C13: Month-by-month KPI calculations built with formulas (SUMIFS, COUNTIFS, AVERAGEIFS) referencing the raw data sheets.
B14: Student_Exercise | C14: The same dashboard layout with formulas removed — fill in the blank yellow cells yourself.
B16: KPI formula reference (from the source article)
B17: CSAT | C17: (Number of satisfied responses ÷ Total number of responses) × 100 Note: A response counts as 'satisfied' when the CSAT score is 4 or 5 on the 1–5 scale.
B18: NPS | C18: % Promoters − % Detractors Note: Promoters score 9–10, Passives score 7–8, Detractors score 0–6 (0–10 scale).
B19: CES | C19: Sum of responses ÷ Total number of responses (× 100 per the source article) Note: Effort scale used here is 1 (very high effort) to 7 (very low effort).
B20: Churn Rate | C20: (Customers lost during period ÷ Total customers at start of period) × 100 Note: Calculated per calendar month in this file.
B21: FCR | C21: Number of incidents resolved on first contact ÷ Total incidents Note: Shown as a percentage in this file.
B22: CLV | C22: Average purchase value × Number of purchases across the customer journey Note: Calculated per customer, then averaged by segment.
B24: Suggested student exercises
B25: 1. Open KPI_Dashboard and trace each formula back to Support_Tickets, NPS_Survey, or Customer_Accounts.
B26: 2. Open Student_Exercise and rebuild the formulas from scratch in the yellow cells.
B27: 3. Which support channel has the highest FCR? Which has the lowest CSAT? Use a PivotTable on Support_Tickets to find out.
B28: 4. Compare CLV between the Consumer and Small Business segments on Customer_Accounts.
B29: 5. Identify which month had the highest churn rate and propose two reasons why, using the IssueCategory data as a clue.
B30: 6. Build a chart showing CSAT, FCR, and CES trending over the 6 months on KPI_Dashboard.

Sheet Pivots For Quality
C16: Count of CSAT Status | D16: Column Labels | H16: Count of NPS Status | I16: Column Labels | M16: Count of CES Status | N16: Column Labels | R16: ChurnDate(month) | S16: Count of CustomerID | U16: SignupDate | V16: Count of CustomerID | X16: Count of CustomerID | Y16: Column Labels
C17: Row Labels | D17: Satisfied | E17: Unsatisfied | F17: Grand Total | H17: Row Labels | I17: Detractors | J17: Promoters | K17: Grand Total | M17: Row Labels | N17: High Effort | O17: Low Effort | P17: Grand Total | R17: Jan | S17: 3 | U17: Jan | V17: 26 | X17: SignupDate | Y17: Active | Z17: Churned | AA17: Grand Total
C18: Jan | D18: 0.55769231 | E18: 0.44230769 | F18: 1 | H18: Jan | I18: 0.20689655 | J18: 0.79310345 | K18: 1 | M18: Jan | N18: 0.41176471 | O18: 0.58823529 | P18: 1 | R18: Feb | S18: 6 | U18: Feb | V18: 9 | X18: 2024
C19: Feb | D19: 0.55 | E19: 0.45 | F19: 1 | H19: Feb | I19: 0.22580645 | J19: 0.77419355 | K19: 1 | M19: Feb | N19: 0.3902439 | O19: 0.6097561 | P19: 1 | R19: Mar | S19: 7 | U19: Mar | V19: 27 | X19: Jan | Y19: 8 | Z19: 3 | AA19: 11
C20: Mar | D20: 0.64473684 | E20: 0.35526316 | F20: 1 | H20: Mar | I20: 0.38888889 | J20: 0.61111111 | K20: 1 | M20: Mar | N20: 0.34782609 | O20: 0.65217391 | P20: 1 | R20: Apr | S20: 11 | U20: Apr | V20: 34 | X20: Feb | Y20: 6 | AA20: 6
C21: Apr | D21: 0.734375 | E21: 0.265625 | F21: 1 | H21: Apr | I21: 0.28571429 | J21: 0.71428571 | K21: 1 | M21: Apr | N21: 0.29411765 | O21: 0.70588235 | P21: 1 | R21: May | S21: 4 | U21: May | V21: 17 | X21: Mar | Y21: 8 | Z21: 2 | AA21: 10
C22: May | D22: 0.65333333 | E22: 0.34666667 | F22: 1 | H22: May | I22: 0.45714286 | J22: 0.54285714 | K22: 1 | M22: May | N22: 0.39583333 | O22: 0.60416667 | P22: 1 | R22: Jun | S22: 8 | U22: Jun | V22: 25 | X22: Apr | Y22: 11 | Z22: 3 | AA22: 14
C23: Jun | D23: 0.57971014 | E23: 0.42028986 | F23: 1 | H23: Jun | I23: 0.35135135 | J23: 0.64864865 | K23: 1 | M23: Jun | N23: 0.36585366 | O23: 0.63414634 | P23: 1 | R23: Grand Total | S23: 39 | U23: Jul | V23: 22 | X23: May | Y23: 9 | AA23: 9
C24: Grand Total | D24: 0.62373737 | E24: 0.37626263 | F24: 1 | H24: Grand Total | I24: 0.32653061 | J24: 0.67346939 | K24: 1 | M24: Grand Total | N24: 0.36885246 | O24: 0.63114754 | P24: 1 | U24: Aug | V24: 17 | X24: Jun | Y24: 8 | Z24: 2 | AA24: 10
U25: Sep | V25: 23 | X25: Jul | Y25: 9 | Z25: 1 | AA25: 10
R26: Row Labels | S26: Count of CustomerID | U26: Oct | V26: 19 | X26: Aug | Y26: 9 | Z26: 2 | AA26: 11
C27: Count of FCR (First Contact Resolution) | D27: Column Labels | H27: Month | I27: CSAT (Satisfied%) | J27: NPS (Promoters%) | K27: CES (Low Effort%) | R27: Active | S27: 221 | U27: Nov | V27: 24 | X27: Sep | Y27: 7 | AA27: 7
C28: Row Labels | D28: No | E28: Yes | F28: Grand Total | H28: Jan | I28: =D18 -> 0.55769231 | J28: =J18 -> 0.79310345 | K28: =O18 -> 0.58823529 | R28: Churned | S28: 39 | U28: Dec | V28: 17 | X28: Oct | Y28: 13 | Z28: 2 | AA28: 15
C29: Jan | D29: 0.27692308 | E29: 0.72307692 | F29: 1 | H29: Feb | I29: =D19 -> 0.55 | J29: =J19 -> 0.77419355 | K29: =O19 -> 0.6097561 | R29: Grand Total | S29: 260 | U29: Grand Total | V29: 260 | X29: Nov | Y29: 8 | Z29: 3 | AA29: 11
C30: Feb | D30: 0.32467532 | E30: 0.67532468 | F30: 1 | H30: Mar | I30: =D20 -> 0.64473684 | J30: =J20 -> 0.61111111 | K30: =O20 -> 0.65217391 | X30: Dec | Y30: 16 | Z30: 1 | AA30: 17
C31: Mar | D31: 0.29473684 | E31: 0.70526316 | F31: 1 | H31: Apr | I31: =D21 -> 0.734375 | J31: =J21 -> 0.71428571 | K31: =O21 -> 0.70588235 | X31: 2025
C32: Apr | D32: 0.19736842 | E32: 0.80263158 | F32: 1 | H32: May | I32: =D22 -> 0.65333333 | J32: =J22 -> 0.54285714 | K32: =O22 -> 0.60416667 | X32: Jan | Y32: 13 | Z32: 2 | AA32: 15
C33: May | D33: 0.2247191 | E33: 0.7752809 | F33: 1 | H33: Jun | I33: =D23 -> 0.57971014 | J33: =J23 -> 0.64864865 | K33: =O23 -> 0.63414634 | R33: Month | S33: Current Customers | T33: Churned | U33: Churn Rate | X33: Feb | Y33: 3 | AA33: 3
C34: Jun | D34: 0.28205128 | E34: 0.71794872 | F34: 1 | R34: =R17 -> Jan | S34: 26 | T34: =S17 -> 3 | U34: =T34/S34 -> 0.11538462 | X34: Mar | Y34: 15 | Z34: 2 | AA34: 17 | AC34: Row Labels | AD34: Average of Churn Rate
C35: Grand Total | D35: 0.26666667 | E35: 0.73333333 | F35: 1 | R35: =R18 -> Feb | S35: =(V18+(S34-T34)) -> 32 | T35: =S18 -> 6 | U35: =T35/S35 -> 0.1875 | X35: Apr | Y35: 17 | Z35: 3 | AA35: 20 | AC35: Jan | AD35: 1.15
H36: Month | I36: CSAT (Satisfied%) | J36: NPS (Promoters%) | K36: CES (Low Effort%) | R36: =R19 -> Mar | S36: =(V19+(S35-T35)) -> 53 | T36: =S19 -> 7 | U36: =T36/S36 -> 0.13207547 | X36: May | Y36: 6 | Z36: 2 | AA36: 8 | AC36: Feb | AD36: 2.33
C37: Month | D37: FCR Rate | H37: Apr | I37: 0.734375 | J37: 0.71428571 | K37: =K31 -> 0.70588235 | R37: =R20 -> Apr | S37: =(V20+(S36-T36)) -> 80 | T37: =S20 -> 11 | U37: =T37/S37 -> 0.1375 | X37: Jun | Y37: 11 | Z37: 4 | AA37: 15 | AC37: Mar | AD37: 2.79
C38: =C29 -> Jan | D38: =E29 -> 0.72307692 | R38: =R21 -> May | S38: =(V21+(S37-T37)) -> 86 | T38: =S21 -> 4 | U38: =T38/S38 -> 0.046511628 | X38: Jul | Y38: 11 | Z38: 1 | AA38: 12 | AC38: Apr | AD38: 4.51
C39: =C30 -> Feb | D39: =E30 -> 0.67532468 | H39: Month | I39: CSAT (Satisfied%) | J39: NPS (Promoters%) | K39: CES (Low Effort%) | R39: =R22 -> Jun | S39: =(V22+(S38-T38)) -> 107 | T39: =S22 -> 8 | U39: =T39/S39 -> 0.074766355 | X39: Aug | Y39: 6 | AA39: 6 | AC39: May | AD39: 1.72
C40: =C31 -> Mar | D40: =E31 -> 0.70526316 | H40: Jun | I40: 0.57971014 | J40: 0.64864865 | K40: =K33 -> 0.63414634 | X40: Sep | Y40: 15 | Z40: 1 | AA40: 16 | AC40: Jun | AD40: 3.49
C41: =C32 -> Apr | D41: =E32 -> 0.80263158 | X41: Oct | Y41: 3 | Z41: 1 | AA41: 4 | AC41: Grand Total | AD41: 2.665
C42: =C33 -> May | D42: =E33 -> 0.7752809 | R42: Month | S42: Churn Rate | T42: High Effort | X42: Nov | Y42: 9 | Z42: 4 | AA42: 13
C43: =C34 -> Jun | D43: =E34 -> 0.71794872 | R43: =R34 -> Jan | S43: =ROUND(COUNTIFS(Customer_Accounts!$J$2:$J$261,">="&DATE(2026,1,1),Customer_Accounts!$J$2:$J$261,"<"&DATE(2026,1+1,1))/(COUNTIFS(Customer_Accounts!$C$2:$C$261,"<"&DATE(2026,1,1),Customer_Accounts!$J$2:$J$261,">="&DATE(2026,1,1))+COUNTIFS(Customer_Accounts!$C$2:$C$261,"<"&DATE(2026,1,1),Customer_Accounts!$J$2:$J$261,""))*100,2) -> 1.15 | T43: =N18 -> 0.41176471 | X43: Grand Total | Y43: 221 | Z43: 39 | AA43: 260
R44: =R35 -> Feb | S44: =ROUND(COUNTIFS(Customer_Accounts!$J$2:$J$261,">="&DATE(2026,2,1),Customer_Accounts!$J$2:$J$261,"<"&DATE(2026,2+1,1))/(COUNTIFS(Customer_Accounts!$C$2:$C$261,"<"&DATE(2026,2,1),Customer_Accounts!$J$2:$J$261,">="&DATE(2026,2,1))+COUNTIFS(Customer_Accounts!$C$2:$C$261,"<"&DATE(2026,2,1),Customer_Accounts!$J$2:$J$261,""))*100,2) -> 2.33 | T44: =N19 -> 0.3902439
R45: =R36 -> Mar | S45: =ROUND(COUNTIFS(Customer_Accounts!$J$2:$J$261,">="&DATE(2026,3,1),Customer_Accounts!$J$2:$J$261,"<"&DATE(2026,3+1,1))/(COUNTIFS(Customer_Accounts!$C$2:$C$261,"<"&DATE(2026,3,1),Customer_Accounts!$J$2:$J$261,">="&DATE(2026,3,1))+COUNTIFS(Customer_Accounts!$C$2:$C$261,"<"&DATE(2026,3,1),Customer_Accounts!$J$2:$J$261,""))*100,2) -> 2.79 | T45: =N20 -> 0.34782609 | W45: Count of Status | X45: Column Labels
C46: Row Labels | D46: Count of NPS Status | F46: Row Labels | G46: Count of FCR (First Contact Resolution) | I46: Row Labels | J46: Count of CSAT Status | L46: Row Labels | M46: Count of CES Status | O46: Average of TotalRevenue | R46: =R37 -> Apr | S46: =ROUND(COUNTIFS(Customer_Accounts!$J$2:$J$261,">="&DATE(2026,4,1),Customer_Accounts!$J$2:$J$261,"<"&DATE(2026,4+1,1))/(COUNTIFS(Customer_Accounts!$C$2:$C$261,"<"&DATE(2026,4,1),Customer_Accounts!$J$2:$J$261,">="&DATE(2026,4,1))+COUNTIFS(Customer_Accounts!$C$2:$C$261,"<"&DATE(2026,4,1),Customer_Accounts!$J$2:$J$261,""))*100,2) -> 4.51 | T46: =N21 -> 0.29411765 | W46: Row Labels | X46: Active | Y46: Churned | Z46: Grand Total
C47: Detractors | D47: 0.22068966 | F47: No | G47: 0.26666667 | I47: Satisfied | J47: 0.62373737 | L47: High Effort | M47: 0.36885246 | O47: 4060.3158 | R47: =R38 -> May | S47: =ROUND(COUNTIFS(Customer_Accounts!$J$2:$J$261,">="&DATE(2026,5,1),Customer_Accounts!$J$2:$J$261,"<"&DATE(2026,5+1,1))/(COUNTIFS(Customer_Accounts!$C$2:$C$261,"<"&DATE(2026,5,1),Customer_Accounts!$J$2:$J$261,">="&DATE(2026,5,1))+COUNTIFS(Customer_Accounts!$C$2:$C$261,"<"&DATE(2026,5,1),Customer_Accounts!$J$2:$J$261,""))*100,2) -> 1.72 | T47: =N22 -> 0.39583333 | W47: Asia Pacific | X47: 0.88571429 | Y47: 0.11428571 | Z47: 1
C48: Passive | D48: 0.32413793 | F48: Yes | G48: 0.73333333 | I48: Unsatisfied | J48: 0.37626263 | L48: Low Effort | M48: 0.63114754 | R48: =R39 -> Jun | S48: =ROUND(COUNTIFS(Customer_Accounts!$J$2:$J$261,">="&DATE(2026,6,1),Customer_Accounts!$J$2:$J$261,"<"&DATE(2026,6+1,1))/(COUNTIFS(Customer_Accounts!$C$2:$C$261,"<"&DATE(2026,6,1),Customer_Accounts!$J$2:$J$261,">="&DATE(2026,6,1))+COUNTIFS(Customer_Accounts!$C$2:$C$261,"<"&DATE(2026,6,1),Customer_Accounts!$J$2:$J$261,""))*100,2) -> 3.49 | T48: =N23 -> 0.36585366 | W48: Europe | X48: 0.81538462 | Y48: 0.18461538 | Z48: 1
C49: Promoters | D49: 0.45517241 | F49: Grand Total | G49: 1 | I49: Grand Total | J49: 1 | L49: Grand Total | M49: 1 | R49: Gand | S49: =AVERAGE(S43:S48) -> 2.665 | T49: =N24 -> 0.36885246 | W49: Latin America | X49: 0.79104478 | Y49: 0.20895522 | Z49: 1
C50: Grand Total | D50: 1 | W50: North America | X50: 0.9137931 | Y50: 0.086206897 | Z50: 1
W51: Grand Total | X51: 0.85 | Y51: 0.15 | Z51: 1
R52: Month | S52: CES | T52: Churn Rate
R53: =R43 -> Jan | T53: =S43 -> 1.15 | W53: Region | X53: Churn Rate
R54: =R44 -> Feb | T54: =S44 -> 2.33 | W54: =W47 -> Asia Pacific | X54: =Y47 -> 0.11428571
R55: =R45 -> Mar | T55: =S45 -> 2.79 | W55: =W48 -> Europe | X55: =Y48 -> 0.18461538
...

Sheet Quality Dashboard

Sheet Home

Sheet NPS Dashboard

Sheet CSAT Dashboard

Sheet Insights

Sheet NPS_Survey
A1: ResponseID | B1: Date | C1: CustomerID | D1: NPS_Score (0-10) | E1: Quarter | F1: NPS Status
A2: NPS-0049 | B2: 46027 | C2: CUST-1011 | D2: 6 | E2: Q1 2026 | F2: {=_xlfn.IFS(NPSTable[[#This Row],[NPS_Score (0-10)]]>=9,"Promoters",NPSTable[[#This Row],[NPS_Score (0-10)]]<=6,"Detractors", OR(NPSTable[[#This Row],[NPS_Score (0-10)]]=7,NPSTable[[#This Row],[NPS_Score (0-10)]]=8),"Passive")} -> Detractors
A3: NPS-0062 | B3: 46028 | C3: CUST-1236 | D3: 9 | E3: Q1 2026 | F3: {=_xlfn.IFS(NPSTable[[#This Row],[NPS_Score (0-10)]]>=9,"Promoters",NPSTable[[#This Row],[NPS_Score (0-10)]]<=6,"Detractors", OR(NPSTable[[#This Row],[NPS_Score (0-10)]]=7,NPSTable[[#This Row],[NPS_Score (0-10)]]=8),"Passive")} -> Promoters
A4: NPS-0075 | B4: 46028 | C4: CUST-1189 | D4: 10 | E4: Q1 2026 | F4: {=_xlfn.IFS(NPSTable[[#This Row],[NPS_Score (0-10)]]>=9,"Promoters",NPSTable[[#This Row],[NPS_Score (0-10)]]<=6,"Detractors", OR(NPSTable[[#This Row],[NPS_Score (0-10)]]=7,NPSTable[[#This Row],[NPS_Score (0-10)]]=8),"Passive")} -> Promoters
A5: NPS-0020 | B5: 46029 | C5: CUST-1024 | D5: 7 | E5: Q1 2026 | F5: {=_xlfn.IFS(NPSTable[[#This Row],[NPS_Score (0-10)]]>=9,"Promoters",NPSTable[[#This Row],[NPS_Score (0-10)]]<=6,"Detractors", OR(NPSTable[[#This Row],[NPS_Score (0-10)]]=7,NPSTable[[#This Row],[NPS_Score (0-10)]]=8),"Passive")} -> Passive | H5: Row Labels | I5: Count of NPS Status | K5: Row Labels | L5: Count of NPS Status | N5: Count of NPS Status | O5: Column Labels
A6: NPS-0090 | B6: 46030 | C6: CUST-1079 | D6: 10 | E6: Q1 2026 | F6: {=_xlfn.IFS(NPSTable[[#This Row],[NPS_Score (0-10)]]>=9,"Promoters",NPSTable[[#This Row],[NPS_Score (0-10)]]<=6,"Detractors", OR(NPSTable[[#This Row],[NPS_Score (0-10)]]=7,NPSTable[[#This Row],[NPS_Score (0-10)]]=8),"Passive")} -> Promoters | H6: Detractors | I6: 64 | K6: Detractors | L6: 0.22068966 | N6: Row Labels | O6: Detractors | P6: Passive | Q6: Promoters | R6: Grand Total
A7: NPS-0029 | B7: 46032 | C7: CUST-1095 | D7: 9 | E7: Q1 2026 | F7: {=_xlfn.IFS(NPSTable[[#This Row],[NPS_Score (0-10)]]>=9,"Promoters",NPSTable[[#This Row],[NPS_Score (0-10)]]<=6,"Detractors", OR(NPSTable[[#This Row],[NPS_Score (0-10)]]=7,NPSTable[[#This Row],[NPS_Score (0-10)]]=8),"Passive")} -> Promoters | H7: Passive | I7: 94 | K7: Passive | L7: 0.32413793 | N7: Jan | O7: 6 | P7: 16 | Q7: 23 | R7: 45 | S7: =N7 -> Jan | T7: =(Q7-O7)/R7 -> 0.37777778 | V7: Count of NPS Status | W7: Column Labels
A8: NPS-0038 | B8: 46032 | C8: CUST-1212 | D8: 8 | E8: Q1 2026 | F8: {=_xlfn.IFS(NPSTable[[#This Row],[NPS_Score (0-10)]]>=9,"Promoters",NPSTable[[#This Row],[NPS_Score (0-10)]]<=6,"Detractors", OR(NPSTable[[#This Row],[NPS_Score (0-10)]]=7,NPSTable[[#This Row],[NPS_Score (0-10)]]=8),"Passive")} -> Passive | H8: Promoters | I8: 132 | K8: Promoters | L8: 0.45517241 | N8: Feb | O8: 7 | P8: 14 | Q8: 24 | R8: 45 | S8: =N8 -> Feb | T8: =(Q8-O8)/R8 -> 0.37777778 | V8: Row Labels | W8: Detractors | X8: Passive | Y8: Promoters | Z8: Grand Total
A9: NPS-0134 | B9: 46032 | C9: CUST-1037 | D9: 8 | E9: Q1 2026 | F9: {=_xlfn.IFS(NPSTable[[#This Row],[NPS_Score (0-10)]]>=9,"Promoters",NPSTable[[#This Row],[NPS_Score (0-10)]]<=6,"Detractors", OR(NPSTable[[#This Row],[NPS_Score (0-10)]]=7,NPSTable[[#This Row],[NPS_Score (0-10)]]=8),"Passive")} -> Passive | H9: Grand Total | I9: 290 | K9: Grand Total | L9: 1 | N9: Mar | O9: 14 | P9: 14 | Q9: 22 | R9: 50 | S9: =N9 -> Mar | T9: =(Q9-O9)/R9 -> 0.16 | V9: Active | W9: 55 | X9: 84 | Y9: 112 | Z9: 251 | AA9: =V9 -> Active | AB9: =(Y9-W9)/Z9 -> 0.22709163
A10: NPS-0095 | B10: 46034 | C10: CUST-1094 | D10: 10 | E10: Q1 2026 | F10: {=_xlfn.IFS(NPSTable[[#This Row],[NPS_Score (0-10)]]>=9,"Promoters",NPSTable[[#This Row],[NPS_Score (0-10)]]<=6,"Detractors", OR(NPSTable[[#This Row],[NPS_Score (0-10)]]=7,NPSTable[[#This Row],[NPS_Score (0-10)]]=8),"Passive")} -> Promoters | N10: Apr | O10: 8 | P10: 18 | Q10: 20 | R10: 46 | S10: =N10 -> Apr | T10: =(Q10-O10)/R10 -> 0.26086957 | V10: Churned | W10: 9 | X10: 10 | Y10: 20 | Z10: 39 | AA10: =V10 -> Churned | AB10: =(Y10-W10)/Z10 -> 0.28205128
A11: NPS-0113 | B11: 46034 | C11: CUST-1010 | D11: 8 | E11: Q1 2026 | F11: {=_xlfn.IFS(NPSTable[[#This Row],[NPS_Score (0-10)]]>=9,"Promoters",NPSTable[[#This Row],[NPS_Score (0-10)]]<=6,"Detractors", OR(NPSTable[[#This Row],[NPS_Score (0-10)]]=7,NPSTable[[#This Row],[NPS_Score (0-10)]]=8),"Passive")} -> Passive | K11: NPS % | L11: =L8-L6 -> 0.23448276 | N11: May | O11: 16 | P11: 14 | Q11: 19 | R11: 49 | S11: =N11 -> May | T11: =(Q11-O11)/R11 -> 0.06122449 | V11: Grand Total | W11: 64 | X11: 94 | Y11: 132 | Z11: 290
A12: NPS-0024 | B12: 46035 | C12: CUST-1072 | D12: 7 | E12: Q1 2026 | F12: {=_xlfn.IFS(NPSTable[[#This Row],[NPS_Score (0-10)]]>=9,"Promoters",NPSTable[[#This Row],[NPS_Score (0-10)]]<=6,"Detractors", OR(NPSTable[[#This Row],[NPS_Score (0-10)]]=7,NPSTable[[#This Row],[NPS_Score (0-10)]]=8),"Passive")} -> Passive | N12: Jun | O12: 13 | P12: 18 | Q12: 24 | R12: 55 | S12: =N12 -> Jun | T12: =(Q12-O12)/R12 -> 0.2
A13: NPS-0064 | B13: 46037 | C13: CUST-1014 | D13: 7 | E13: Q1 2026 | F13: {=_xlfn.IFS(NPSTable[[#This Row],[NPS_Score (0-10)]]>=9,"Promoters",NPSTable[[#This Row],[NPS_Score (0-10)]]<=6,"Detractors", OR(NPSTable[[#This Row],[NPS_Score (0-10)]]=7,NPSTable[[#This Row],[NPS_Score (0-10)]]=8),"Passive")} -> Passive | N13: Grand Total | O13: 64 | P13: 94 | Q13: 132 | R13: 290
A14: NPS-0014 | B14: 46038 | C14: CUST-1235 | D14: 9 | E14: Q1 2026 | F14: {=_xlfn.IFS(NPSTable[[#This Row],[NPS_Score (0-10)]]>=9,"Promoters",NPSTable[[#This Row],[NPS_Score (0-10)]]<=6,"Detractors", OR(NPSTable[[#This Row],[NPS_Score (0-10)]]=7,NPSTable[[#This Row],[NPS_Score (0-10)]]=8),"Passive")} -> Promoters
A15: NPS-0087 | B15: 46038 | C15: CUST-1076 | D15: 8 | E15: Q1 2026 | F15: {=_xlfn.IFS(NPSTable[[#This Row],[NPS_Score (0-10)]]>=9,"Promoters",NPSTable[[#This Row],[NPS_Score (0-10)]]<=6,"Detractors", OR(NPSTable[[#This Row],[NPS_Score (0-10)]]=7,NPSTable[[#This Row],[NPS_Score (0-10)]]=8),"Passive")} -> Passive | N15: Count of NPS Status | O15: Column Labels
A16: NPS-0017 | B16: 46039 | C16: CUST-1250 | D16: 10 | E16: Q1 2026 | F16: {=_xlfn.IFS(NPSTable[[#This Row],[NPS_Score (0-10)]]>=9,"Promoters",NPSTable[[#This Row],[NPS_Score (0-10)]]<=6,"Detractors", OR(NPSTable[[#This Row],[NPS_Score (0-10)]]=7,NPSTable[[#This Row],[NPS_Score (0-10)]]=8),"Passive")} -> Promoters | N16: Row Labels | O16: Detractors | P16: Passive | Q16: Promoters | R16: Grand Total
A17: NPS-0044 | B17: 46039 | C17: CUST-1068 | D17: 5 | E17: Q1 2026 | F17: {=_xlfn.IFS(NPSTable[[#This Row],[NPS_Score (0-10)]]>=9,"Promoters",NPSTable[[#This Row],[NPS_Score (0-10)]]<=6,"Detractors", OR(NPSTable[[#This Row],[NPS_Score (0-10)]]=7,NPSTable[[#This Row],[NPS_Score (0-10)]]=8),"Passive")} -> Detractors | N17: Q1 2026 | O17: 27 | P17: 44 | Q17: 69 | R17: 140 | S17: =N17 -> Q1 2026 | T17: =(Q17-O17)/R17 -> 0.3
A18: NPS-0033 | B18: 46040 | C18: CUST-1082 | D18: 9 | E18: Q1 2026 | F18: {=_xlfn.IFS(NPSTable[[#This Row],[NPS_Score (0-10)]]>=9,"Promoters",NPSTable[[#This Row],[NPS_Score (0-10)]]<=6,"Detractors", OR(NPSTable[[#This Row],[NPS_Score (0-10)]]=7,NPSTable[[#This Row],[NPS_Score (0-10)]]=8),"Passive")} -> Promoters | N18: Q2 2026 | O18: 37 | P18: 50 | Q18: 63 | R18: 150 | S18: =N18 -> Q2 2026 | T18: =(Q18-O18)/R18 -> 0.17333333
A19: NPS-0037 | B19: 46040 | C19: CUST-1117 | D19: 10 | E19: Q1 2026 | F19: {=_xlfn.IFS(NPSTable[[#This Row],[NPS_Score (0-10)]]>=9,"Promoters",NPSTable[[#This Row],[NPS_Score (0-10)]]<=6,"Detractors", OR(NPSTable[[#This Row],[NPS_Score (0-10)]]=7,NPSTable[[#This Row],[NPS_Score (0-10)]]=8),"Passive")} -> Promoters | N19: Grand Total | O19: 64 | P19: 94 | Q19: 132 | R19: 290
A20: NPS-0025 | B20: 46041 | C20: CUST-1174 | D20: 9 | E20: Q1 2026 | F20: {=_xlfn.IFS(NPSTable[[#This Row],[NPS_Score (0-10)]]>=9,"Promoters",NPSTable[[#This Row],[NPS_Score (0-10)]]<=6,"Detractors", OR(NPSTable[[#This Row],[NPS_Score (0-10)]]=7,NPSTable[[#This Row],[NPS_Score (0-10)]]=8),"Passive")} -> Promoters
A21: NPS-0035 | B21: 46041 | C21: CUST-1007 | D21: 10 | E21: Q1 2026 | F21: {=_xlfn.IFS(NPSTable[[#This Row],[NPS_Score (0-10)]]>=9,"Promoters",NPSTable[[#This Row],[NPS_Score (0-10)]]<=6,"Detractors", OR(NPSTable[[#This Row],[NPS_Score (0-10)]]=7,NPSTable[[#This Row],[NPS_Score (0-10)]]=8),"Passive")} -> Promoters
A22: NPS-0026 | B22: 46042 | C22: CUST-1246 | D22: 8 | E22: Q1 2026 | F22: {=_xlfn.IFS(NPSTable[[#This Row],[NPS_Score (0-10)]]>=9,"Promoters",NPSTable[[#This Row],[NPS_Score (0-10)]]<=6,"Detractors", OR(NPSTable[[#This Row],[NPS_Score (0-10)]]=7,NPSTable[[#This Row],[NPS_Score (0-10)]]=8),"Passive")} -> Passive | N22: Count of NPS Status | O22: Column Labels
A23: NPS-0098 | B23: 46042 | C23: CUST-1172 | D23: 8 | E23: Q1 2026 | F23: {=_xlfn.IFS(NPSTable[[#This Row],[NPS_Score (0-10)]]>=9,"Promoters",NPSTable[[#This Row],[NPS_Score (0-10)]]<=6,"Detractors", OR(NPSTable[[#This Row],[NPS_Score (0-10)]]=7,NPSTable[[#This Row],[NPS_Score (0-10)]]=8),"Passive")} -> Passive | N23: Row Labels | O23: Detractors | P23: Passive | Q23: Promoters | R23: Grand Total
A24: NPS-0127 | B24: 46042 | C24: CUST-1219 | D24: 9 | E24: Q1 2026 | F24: {=_xlfn.IFS(NPSTable[[#This Row],[NPS_Score (0-10)]]>=9,"Promoters",NPSTable[[#This Row],[NPS_Score (0-10)]]<=6,"Detractors", OR(NPSTable[[#This Row],[NPS_Score (0-10)]]=7,NPSTable[[#This Row],[NPS_Score (0-10)]]=8),"Passive")} -> Promoters | N24: Asia Pacific | O24: 16 | P24: 23 | Q24: 31 | R24: 70 | S24: =N24 -> Asia Pacific | T24: =(Q24-O24)/R24 -> 0.21428571
A25: NPS-0131 | B25: 46042 | C25: CUST-1132 | D25: 9 | E25: Q1 2026 | F25: {=_xlfn.IFS(NPSTable[[#This Row],[NPS_Score (0-10)]]>=9,"Promoters",NPSTable[[#This Row],[NPS_Score (0-10)]]<=6,"Detractors", OR(NPSTable[[#This Row],[NPS_Score (0-10)]]=7,NPSTable[[#This Row],[NPS_Score (0-10)]]=8),"Passive")} -> Promoters | N25: Europe | O25: 15 | P25: 19 | Q25: 37 | R25: 71 | S25: =N25 -> Europe | T25: =(Q25-O25)/R25 -> 0.30985915
A26: NPS-0135 | B26: 46042 | C26: CUST-1178 | D26: 7 | E26: Q1 2026 | F26: {=_xlfn.IFS(NPSTable[[#This Row],[NPS_Score (0-10)]]>=9,"Promoters",NPSTable[[#This Row],[NPS_Score (0-10)]]<=6,"Detractors", OR(NPSTable[[#This Row],[NPS_Score (0-10)]]=7,NPSTable[[#This Row],[NPS_Score (0-10)]]=8),"Passive")} -> Passive | N26: Latin America | O26: 15 | P26: 33 | Q26: 36 | R26: 84 | S26: =N26 -> Latin America | T26: =(Q26-O26)/R26 -> 0.25
A27: NPS-0015 | B27: 46043 | C27: CUST-1019 | D27: 5 | E27: Q1 2026 | F27: {=_xlfn.IFS(NPSTable[[#This Row],[NPS_Score (0-10)]]>=9,"Promoters",NPSTable[[#This Row],[NPS_Score (0-10)]]<=6,"Detractors", OR(NPSTable[[#This Row],[NPS_Score (0-10)]]=7,NPSTable[[#This Row],[NPS_Score (0-10)]]=8),"Passive")} -> Detractors | N27: North America | O27: 18 | P27: 19 | Q27: 28 | R27: 65 | S27: =N27 -> North America | T27: =(Q27-O27)/R27 -> 0.15384615
A28: NPS-0085 | B28: 46043 | C28: CUST-1226 | D28: 8 | E28: Q1 2026 | F28: {=_xlfn.IFS(NPSTable[[#This Row],[NPS_Score (0-10)]]>=9,"Promoters",NPSTable[[#This Row],[NPS_Score (0-10)]]<=6,"Detractors", OR(NPSTable[[#This Row],[NPS_Score (0-10)]]=7,NPSTable[[#This Row],[NPS_Score (0-10)]]=8),"Passive")} -> Passive | N28: Grand Total | O28: 64 | P28: 94 | Q28: 132 | R28: 290
A29: NPS-0114 | B29: 46043 | C29: CUST-1199 | D29: 8 | E29: Q1 2026 | F29: {=_xlfn.IFS(NPSTable[[#This Row],[NPS_Score (0-10)]]>=9,"Promoters",NPSTable[[#This Row],[NPS_Score (0-10)]]<=6,"Detractors", OR(NPSTable[[#This Row],[NPS_Score (0-10)]]=7,NPSTable[[#This Row],[NPS_Score (0-10)]]=8),"Passive")} -> Passive
A30: NPS-0125 | B30: 46043 | C30: CUST-1150 | D30: 10 | E30: Q1 2026 | F30: {=_xlfn.IFS(NPSTable[[#This Row],[NPS_Score (0-10)]]>=9,"Promoters",NPSTable[[#This Row],[NPS_Score (0-10)]]<=6,"Detractors", OR(NPSTable[[#This Row],[NPS_Score (0-10)]]=7,NPSTable[[#This Row],[NPS_Score (0-10)]]=8),"Passive")} -> Promoters
A31: NPS-0046 | B31: 46044 | C31: CUST-1220 | D31: 5 | E31: Q1 2026 | F31: {=_xlfn.IFS(NPSTable[[#This Row],[NPS_Score (0-10)]]>=9,"Promoters",NPSTable[[#This Row],[NPS_Score (0-10)]]<=6,"Detractors", OR(NPSTable[[#This Row],[NPS_Score (0-10)]]=7,NPSTable[[#This Row],[NPS_Score (0-10)]]=8),"Passive")} -> Detractors | N31: Count of NPS Status | O31: Column Labels
A32: NPS-0077 | B32: 46045 | C32: CUST-1005 | D32: 9 | E32: Q1 2026 | F32: {=_xlfn.IFS(NPSTable[[#This Row],[NPS_Score (0-10)]]>=9,"Promoters",NPSTable[[#This Row],[NPS_Score (0-10)]]<=6,"Detractors", OR(NPSTable[[#This Row],[NPS_Score (0-10)]]=7,NPSTable[[#This Row],[NPS_Score (0-10)]]=8),"Passive")} -> Promoters | N32: Row Labels | O32: Detractors | P32: Passive | Q32: Promoters | R32: Grand Total
A33: NPS-0111 | B33: 46045 | C33: CUST-1109 | D33: 9 | E33: Q1 2026 | F33: {=_xlfn.IFS(NPSTable[[#This Row],[NPS_Score (0-10)]]>=9,"Promoters",NPSTable[[#This Row],[NPS_Score (0-10)]]<=6,"Detractors", OR(NPSTable[[#This Row],[NPS_Score (0-10)]]=7,NPSTable[[#This Row],[NPS_Score (0-10)]]=8),"Passive")} -> Promoters | N33: Consumer | O33: 52 | P33: 76 | Q33: 98 | R33: 226 | S33: =N33 -> Consumer | T33: =(Q33-O33)/R33 -> 0.20353982
A34: NPS-0123 | B34: 46045 | C34: CUST-1074 | D34: 8 | E34: Q1 2026 | F34: {=_xlfn.IFS(NPSTable[[#This Row],[NPS_Score (0-10)]]>=9,"Promoters",NPSTable[[#This Row],[NPS_Score (0-10)]]<=6,"Detractors", OR(NPSTable[[#This Row],[NPS_Score (0-10)]]=7,NPSTable[[#This Row],[NPS_Score (0-10)]]=8),"Passive")} -> Passive | N34: Small Business | O34: 12 | P34: 18 | Q34: 34 | R34: 64 | S34: =N34 -> Small Business | T34: =(Q34-O34)/R34 -> 0.34375
A35: NPS-0138 | B35: 46045 | C35: CUST-1009 | D35: 5 | E35: Q1 2026 | F35: {=_xlfn.IFS(NPSTable[[#This Row],[NPS_Score (0-10)]]>=9,"Promoters",NPSTable[[#This Row],[NPS_Score (0-10)]]<=6,"Detractors", OR(NPSTable[[#This Row],[NPS_Score (0-10)]]=7,NPSTable[[#This Row],[NPS_Score (0-10)]]=8),"Passive")} -> Detractors | N35: Grand Total | O35: 64 | P35: 94 | Q35: 132 | R35: 290
A36: NPS-0031 | B36: 46046 | C36: CUST-1027 | D36: 10 | E36: Q1 2026 | F36: {=_xlfn.IFS(NPSTable[[#This Row],[NPS_Score (0-10)]]>=9,"Promoters",NPSTable[[#This Row],[NPS_Score (0-10)]]<=6,"Detractors", OR(NPSTable[[#This Row],[NPS_Score (0-10)]]=7,NPSTable[[#This Row],[NPS_Score (0-10)]]=8),"Passive")} -> Promoters
A37: NPS-0012 | B37: 46047 | C37: CUST-1046 | D37: 9 | E37: Q1 2026 | F37: {=_xlfn.IFS(NPSTable[[#This Row],[NPS_Score (0-10)]]>=9,"Promoters",NPSTable[[#This Row],[NPS_Score (0-10)]]<=6,"Detractors", OR(NPSTable[[#This Row],[NPS_Score (0-10)]]=7,NPSTable[[#This Row],[NPS_Score (0-10)]]=8),"Passive")} -> Promoters
A38: NPS-0016 | B38: 46047 | C38: CUST-1063 | D38: 9 | E38: Q1 2026 | F38: {=_xlfn.IFS(NPSTable[[#This Row],[NPS_Score (0-10)]]>=9,"Promoters",NPSTable[[#This Row],[NPS_Score (0-10)]]<=6,"Detractors", OR(NPSTable[[#This Row],[NPS_Score (0-10)]]=7,NPSTable[[#This Row],[NPS_Score (0-10)]]=8),"Passive")} -> Promoters
A39: NPS-0022 | B39: 46047 | C39: CUST-1084 | D39: 5 | E39: Q1 2026 | F39: {=_xlfn.IFS(NPSTable[[#This Row],[NPS_Score (0-10)]]>=9,"Promoters",NPSTable[[#This Row],[NPS_Score (0-10)]]<=6,"Detractors", OR(NPSTable[[#This Row],[NPS_Score (0-10)]]=7,NPSTable[[#This Row],[NPS_Score (0-10)]]=8),"Passive")} -> Detractors
A40: NPS-0041 | B40: 46047 | C40: CUST-1122 | D40: 9 | E40: Q1 2026 | F40: {=_xlfn.IFS(NPSTable[[#This Row],[NPS_Score (0-10)]]>=9,"Promoters",NPSTable[[#This Row],[NPS_Score (0-10)]]<=6,"Detractors", OR(NPSTable[[#This Row],[NPS_Score (0-10)]]=7,NPSTable[[#This Row],[NPS_Score (0-10)]]=8),"Passive")} -> Promoters
...

Sheet Customer_Accounts
A1: CustomerID | B1: CustomerName | C1: SignupDate | D1: Segment | E1: Region | F1: TotalPurchases | G1: AvgOrderValue | H1: TotalRevenue | I1: Status | J1: ChurnDate | K1: ChurnMonth
A2: CUST-1000 | B2: Isabella Brown | C2: 45317 | D2: Consumer | E2: Europe | F2: 4 | G2: 105.7 | H2: =F2*G2 -> 422.8 | I2: Churned | J2: 46191 | K2: =IF(J2="","",TEXT(J2,"mmm-yyyy")) -> Jun-2026
A3: CUST-1001 | B3: Sam Thompson | C3: 45724 | D3: Consumer | E3: North America | F3: 4 | G3: 146.21 | H3: =F3*G3 -> 584.84 | I3: Active | K3: =IF(J3="","",TEXT(J3,"mmm-yyyy"))
A4: CUST-1002 | B4: Lucas Davis | C4: 45957 | D4: Consumer | E4: Latin America | F4: 4 | G4: 240.41 | H4: =F4*G4 -> 961.64 | I4: Active | K4: =IF(J4="","",TEXT(J4,"mmm-yyyy"))
A5: CUST-1003 | B5: Grayson Johnson | C5: 45455 | D5: Consumer | E5: Asia Pacific | F5: 5 | G5: 112.63 | H5: =F5*G5 -> 563.15 | I5: Active | K5: =IF(J5="","",TEXT(J5,"mmm-yyyy"))
A6: CUST-1004 | B6: Emma Brown | C6: 45386 | D6: Consumer | E6: Asia Pacific | F6: 14 | G6: 194.62 | H6: =F6*G6 -> 2724.68 | I6: Active | K6: =IF(J6="","",TEXT(J6,"mmm-yyyy"))
A7: CUST-1005 | B7: Jordan Jackson | C7: 45841 | D7: Consumer | E7: Latin America | F7: 2 | G7: 285.14 | H7: =F7*G7 -> 570.28 | I7: Active | K7: =IF(J7="","",TEXT(J7,"mmm-yyyy"))
A8: CUST-1006 | B8: Mason Taylor | C8: 45883 | D8: Consumer | E8: North America | F8: 1 | G8: 332.65 | H8: =F8*G8 -> 332.65 | I8: Active | K8: =IF(J8="","",TEXT(J8,"mmm-yyyy"))
A9: CUST-1007 | B9: Sam Rodriguez | C9: 45395 | D9: Consumer | E9: Latin America | F9: 11 | G9: 407.84 | H9: =F9*G9 -> 4486.24 | I9: Active | K9: =IF(J9="","",TEXT(J9,"mmm-yyyy"))
A10: CUST-1008 | B10: Liam Davis | C10: 45978 | D10: Consumer | E10: North America | F10: 10 | G10: 321.22 | H10: =F10*G10 -> 3212.2 | I10: Active | K10: =IF(J10="","",TEXT(J10,"mmm-yyyy"))
A11: CUST-1009 | B11: Jamie Miller | C11: 45765 | D11: Consumer | E11: Europe | F11: 11 | G11: 186.06 | H11: =F11*G11 -> 2046.66 | I11: Active | K11: =IF(J11="","",TEXT(J11,"mmm-yyyy"))
A12: CUST-1010 | B12: Jordan Rodriguez | C12: 45324 | D12: Small Business | E12: Latin America | F12: 11 | G12: 292.66 | H12: =F12*G12 -> 3219.26 | I12: Active | K12: =IF(J12="","",TEXT(J12,"mmm-yyyy"))
A13: CUST-1011 | B13: Sophia Anderson | C13: 45509 | D13: Consumer | E13: Latin America | F13: 11 | G13: 244.6 | H13: =F13*G13 -> 2690.6 | I13: Active | K13: =IF(J13="","",TEXT(J13,"mmm-yyyy"))
A14: CUST-1012 | B14: Jamie Perez | C14: 45843 | D14: Consumer | E14: Latin America | F14: 10 | G14: 218.74 | H14: =F14*G14 -> 2187.4 | I14: Active | K14: =IF(J14="","",TEXT(J14,"mmm-yyyy"))
... A16: CUST-1014 | B16: Aiden Moore | C16: 45902 | D16: Consumer | E16: Latin America | F16: 10 | G16: 478.31 | H16: =F16*G16 -> 4783.1 | I16: Active | K16: =IF(J16="","",TEXT(J16,"mmm-yyyy"))
A17: CUST-1015 | B17: Lucas Johnson | C17: 45988 | D17: Consumer | E17: Asia Pacific | F17: 13 | G17: 323.82 | H17: =F17*G17 -> 4209.66 | I17: Churned | J17: 46118 | K17: =IF(J17="","",TEXT(J17,"mmm-yyyy")) -> Apr-2026
A18: CUST-1016 | B18: Ava Johnson | C18: 45561 | D18: Small Business | E18: Europe | F18: 19 | G18: 1477.68 | H18: =F18*G18 -> 28075.92 | I18: Active | K18: =IF(J18="","",TEXT(J18,"mmm-yyyy"))
A19: CUST-1017 | B19: Cameron Lee | C19: 45915 | D19: Consumer | E19: Asia Pacific | F19: 13 | G19: 115.27 | H19: =F19*G19 -> 1498.51 | I19: Active | K19: =IF(J19="","",TEXT(J19,"mmm-yyyy"))
A20: CUST-1018 | B20: Wyatt Lee | C20: 45292 | D20: Consumer | E20: Latin America | F20: 1 | G20: 93.66 | H20: =F20*G20 -> 93.66 | I20: Active | K20: =IF(J20="","",TEXT(J20,"mmm-yyyy"))
A21: CUST-1019 | B21: Harper Wilson | C21: 45537 | D21: Consumer | E21: North America | F21: 2 | G21: 363.38 | H21: =F21*G21 -> 726.76 | I21: Active | K21: =IF(J21="","",TEXT(J21,"mmm-yyyy"))
A22: CUST-1020 | B22: Charlotte Perez | C22: 45420 | D22: Consumer | E22: Latin America | F22: 9 | G22: 116.83 | H22: =F22*G22 -> 1051.47 | I22: Active | K22: =IF(J22="","",TEXT(J22,"mmm-yyyy"))
A23: CUST-1021 | B23: Mason Moore | C23: 45508 | D23: Small Business | E23: Europe | F23: 12 | G23: 758.59 | H23: =F23*G23 -> 9103.08 | I23: Active | K23: =IF(J23="","",TEXT(J23,"mmm-yyyy"))
A24: CUST-1022 | B24: Liam Jackson | C24: 45821 | D24: Consumer | E24: Europe | F24: 4 | G24: 72.85 | H24: =F24*G24 -> 291.4 | I24: Churned | J24: 46150 | K24: =IF(J24="","",TEXT(J24,"mmm-yyyy")) -> May-2026
A25: CUST-1023 | B25: Sophia Rodriguez | C25: 45299 | D25: Consumer | E25: North America | F25: 4 | G25: 74.32 | H25: =F25*G25 -> 297.28 | I25: Churned | J25: 46084 | K25: =IF(J25="","",TEXT(J25,"mmm-yyyy")) -> Mar-2026
A26: CUST-1024 | B26: Mia Rodriguez | C26: 45577 | D26: Consumer | E26: Europe | F26: 9 | G26: 102.56 | H26: =F26*G26 -> 923.04 | I26: Active | K26: =IF(J26="","",TEXT(J26,"mmm-yyyy"))
A27: CUST-1025 | B27: Sophia Thompson | C27: 45776 | D27: Consumer | E27: Latin America | F27: 13 | G27: 222.07 | H27: =F27*G27 -> 2886.91 | I27: Churned | J27: 46187 | K27: =IF(J27="","",TEXT(J27,"mmm-yyyy")) -> Jun-2026
A28: CUST-1026 | B28: Liam Moore | C28: 45712 | D28: Consumer | E28: North America | F28: 11 | G28: 329.25 | H28: =F28*G28 -> 3621.75 | I28: Active | K28: =IF(J28="","",TEXT(J28,"mmm-yyyy"))
A29: CUST-1027 | B29: Jordan Thomas | C29: 45639 | D29: Small Business | E29: North America | F29: 10 | G29: 468.23 | H29: =F29*G29 -> 4682.3 | I29: Active | K29: =IF(J29="","",TEXT(J29,"mmm-yyyy"))
A30: CUST-1028 | B30: Morgan Moore | C30: 45479 | D30: Consumer | E30: Europe | F30: 14 | G30: 446.62 | H30: =F30*G30 -> 6252.68 | I30: Active | K30: =IF(J30="","",TEXT(J30,"mmm-yyyy"))
A31: CUST-1029 | B31: Grayson Perez | C31: 45392 | D31: Consumer | E31: North America | F31: 2 | G31: 447.97 | H31: =F31*G31 -> 895.94 | I31: Active | K31: =IF(J31="","",TEXT(J31,"mmm-yyyy"))
A32: CUST-1030 | B32: Casey Moore | C32: 45789 | D32: Consumer | E32: Latin America | F32: 1 | G32: 116.62 | H32: =F32*G32 -> 116.62 | I32: Churned | J32: 46121 | K32: =IF(J32="","",TEXT(J32,"mmm-yyyy")) -> Apr-2026
A33: CUST-1031 | B33: Wyatt Jackson | C33: 45584 | D33: Consumer | E33: Latin America | F33: 3 | G33: 127.61 | H33: =F33*G33 -> 382.83 | I33: Active | K33: =IF(J33="","",TEXT(J33,"mmm-yyyy"))
A34: CUST-1032 | B34: Jordan Thompson | C34: 45847 | D34: Consumer | E34: Asia Pacific | F34: 1 | G34: 66.81 | H34: =F34*G34 -> 66.81 | I34: Active | K34: =IF(J34="","",TEXT(J34,"mmm-yyyy"))
A35: CUST-1033 | B35: Wyatt Lee | C35: 45453 | D35: Consumer | E35: North America | F35: 14 | G35: 125.83 | H35: =F35*G35 -> 1761.62 | I35: Active | K35: =IF(J35="","",TEXT(J35,"mmm-yyyy"))
A36: CUST-1034 | B36: Logan Rodriguez | C36: 45705 | D36: Consumer | E36: Europe | F36: 10 | G36: 303.62 | H36: =F36*G36 -> 3036.2 | I36: Active | K36: =IF(J36="","",TEXT(J36,"mmm-yyyy"))
A37: CUST-1035 | B37: Noah Thompson | C37: 45870 | D37: Consumer | E37: Asia Pacific | F37: 4 | G37: 336.33 | H37: =F37*G37 -> 1345.32 | I37: Active | K37: =IF(J37="","",TEXT(J37,"mmm-yyyy"))
A38: CUST-1036 | B38: Drew Thomas | C38: 45426 | D38: Consumer | E38: Asia Pacific | F38: 8 | G38: 182.54 | H38: =F38*G38 -> 1460.32 | I38: Active | K38: =IF(J38="","",TEXT(J38,"mmm-yyyy"))
A39: CUST-1037 | B39: Sam Johnson | C39: 45761 | D39: Consumer | E39: North America | F39: 2 | G39: 278.87 | H39: =F39*G39 -> 557.74 | I39: Active | K39: =IF(J39="","",TEXT(J39,"mmm-yyyy"))
A40: CUST-1038 | B40: Morgan Taylor | C40: 45362 | D40: Small Business | E40: Asia Pacific | F40: 12 | G40: 420.85 | H40: =F40*G40 -> 5050.2 | I40: Active | K40: =IF(J40="","",TEXT(J40,"mmm-yyyy"))
A41: CUST-1039 | B41: Amelia Wilson | C41: 45918 | D41: Small Business | E41: North America | F41: 20 | G41: 619.13 | H41: =F41*G41 -> 12382.6 | I41: Active | K41: =IF(J41="","",TEXT(J41,"mmm-yyyy"))
...

Sheet Support_Tickets
A1: TicketID | B1: Date | C1: CustomerID | D1: Channel | E1: Agent | F1: IssueCategory | G1: FCR (First Contact Resolution) | H1: ResolutionTimeHours | I1: CSAT_Score (1-5) | J1: CES_Score (1-7) | K1: CSAT Status | L1: CES Status | M1: Column4 | N1: Column1 | O1: Column2
A2: TCK-20629 | B2: 46023 | C2: CUST-1251 | D2: Email | E2: Ahmed Hassan | F2: Technical Support | G2: No | H2: 57.4 | I2: 1 | K2: {=_xlfn.IFS(TicketsTable[[#This Row],[CSAT_Score (1-5)]]>=4,"Satisfied",TicketsTable[[#This Row],[CSAT_Score (1-5)]]>=1,"Unsatisfied",ISBLANK(TicketsTable[[#This Row],[CSAT_Score (1-5)]]),"X")} -> Unsatisfied | L2: {=IFERROR(_xlfn.IFS(OR(TicketsTable[[#This Row],[CES_Score (1-7)]]=1,TicketsTable[[#This Row],[CES_Score (1-7)]]=2,TicketsTable[[#This Row],[CES_Score (1-7)]]=3),"High Effort",OR(TicketsTable[[#This Row],[CES_Score (1-7)]]=6,TicketsTable[[#This Row],[CES_Score (1-7)]]=7),"Low Effort",OR(TicketsTable[[#This Row],[CES_Score (1-7)]]=4,TicketsTable[[#This Row],[CES_Score (1-7)]]=5),"Neutral"),"No Response")} -> No Response | P2: Count of CustomerID | Q2: Distinct Count of Region | R2: Count of ResponseID | S2: Distinct Count of Channel | T2: Sum of TotalRevenue | U2: Average of AvgOrderValue | V2: Distinct Count of Agent | W2: Count of TicketID
A3: TCK-20292 | B3: 46024 | C3: CUST-1211 | D3: Live Chat | E3: Priya Nair | F3: Order Delay | G3: Yes | H3: 1.1 | I3: 3 | J3: 7 | K3: {=_xlfn.IFS(TicketsTable[[#This Row],[CSAT_Score (1-5)]]>=4,"Satisfied",TicketsTable[[#This Row],[CSAT_Score (1-5)]]>=1,"Unsatisfied",ISBLANK(TicketsTable[[#This Row],[CSAT_Score (1-5)]]),"X")} -> Unsatisfied | L3: {=IFERROR(_xlfn.IFS(OR(TicketsTable[[#This Row],[CES_Score (1-7)]]=1,TicketsTable[[#This Row],[CES_Score (1-7)]]=2,TicketsTable[[#This Row],[CES_Score (1-7)]]=3),"High Effort",OR(TicketsTable[[#This Row],[CES_Score (1-7)]]=6,TicketsTable[[#This Row],[CES_Score (1-7)]]=7),"Low Effort",OR(TicketsTable[[#This Row],[CES_Score (1-7)]]=4,TicketsTable[[#This Row],[CES_Score (1-7)]]=5),"Neutral"),"No Response")} -> Low Effort | P3: 260 | Q3: 4 | R3: 290 | S3: 4 | T3: 1055682.1 | U3: 398.07585 | V3: 10 | W3: 480
A4: TCK-20307 | B4: 46024 | C4: CUST-1202 | D4: Live Chat | E4: Nadia Petrov | F4: Product Defect | G4: No | H4: 33.9 | I4: 3 | J4: 2 | K4: {=_xlfn.IFS(TicketsTable[[#This Row],[CSAT_Score (1-5)]]>=4,"Satisfied",TicketsTable[[#This Row],[CSAT_Score (1-5)]]>=1,"Unsatisfied",ISBLANK(TicketsTable[[#This Row],[CSAT_Score (1-5)]]),"X")} -> Unsatisfied | L4: {=IFERROR(_xlfn.IFS(OR(TicketsTable[[#This Row],[CES_Score (1-7)]]=1,TicketsTable[[#This Row],[CES_Score (1-7)]]=2,TicketsTable[[#This Row],[CES_Score (1-7)]]=3),"High Effort",OR(TicketsTable[[#This Row],[CES_Score (1-7)]]=6,TicketsTable[[#This Row],[CES_Score (1-7)]]=7),"Low Effort",OR(TicketsTable[[#This Row],[CES_Score (1-7)]]=4,TicketsTable[[#This Row],[CES_Score (1-7)]]=5),"Neutral"),"No Response")} -> High Effort
A5: TCK-20482 | B5: 46024 | C5: CUST-1060 | D5: Email | E5: Ahmed Hassan | F5: Return/Refund | G5: No | H5: 25.5 | I5: 1 | J5: 2 | K5: {=_xlfn.IFS(TicketsTable[[#This Row],[CSAT_Score (1-5)]]>=4,"Satisfied",TicketsTable[[#This Row],[CSAT_Score (1-5)]]>=1,"Unsatisfied",ISBLANK(TicketsTable[[#This Row],[CSAT_Score (1-5)]]),"X")} -> Unsatisfied | L5: {=IFERROR(_xlfn.IFS(OR(TicketsTable[[#This Row],[CES_Score (1-7)]]=1,TicketsTable[[#This Row],[CES_Score (1-7)]]=2,TicketsTable[[#This Row],[CES_Score (1-7)]]=3),"High Effort",OR(TicketsTable[[#This Row],[CES_Score (1-7)]]=6,TicketsTable[[#This Row],[CES_Score (1-7)]]=7),"Low Effort",OR(TicketsTable[[#This Row],[CES_Score (1-7)]]=4,TicketsTable[[#This Row],[CES_Score (1-7)]]=5),"Neutral"),"No Response")} -> High Effort | P5: Count of CSAT Status | Q5: Column Labels | U5: Count of CSAT Status | V5: Column Labels
A6: TCK-20574 | B6: 46024 | C6: CUST-1125 | D6: Phone | E6: Tom Becker | F6: Return/Refund | G6: Yes | H6: 3.7 | K6: {=_xlfn.IFS(TicketsTable[[#This Row],[CSAT_Score (1-5)]]>=4,"Satisfied",TicketsTable[[#This Row],[CSAT_Score (1-5)]]>=1,"Unsatisfied",ISBLANK(TicketsTable[[#This Row],[CSAT_Score (1-5)]]),"X")} -> X | L6: {=IFERROR(_xlfn.IFS(OR(TicketsTable[[#This Row],[CES_Score (1-7)]]=1,TicketsTable[[#This Row],[CES_Score (1-7)]]=2,TicketsTable[[#This Row],[CES_Score (1-7)]]=3),"High Effort",OR(TicketsTable[[#This Row],[CES_Score (1-7)]]=6,TicketsTable[[#This Row],[CES_Score (1-7)]]=7),"Low Effort",OR(TicketsTable[[#This Row],[CES_Score (1-7)]]=4,TicketsTable[[#This Row],[CES_Score (1-7)]]=5),"Neutral"),"No Response")} -> No Response | P6: Row Labels | Q6: Satisfied | R6: Unsatisfied | S6: Grand Total | U6: Row Labels | V6: Satisfied | W6: Unsatisfied | X6: Grand Total
A7: TCK-20500 | B7: 46025 | C7: CUST-1006 | D7: Email | E7: Ahmed Hassan | F7: Return/Refund | G7: Yes | H7: 2.8 | I7: 5 | J7: 6 | K7: {=_xlfn.IFS(TicketsTable[[#This Row],[CSAT_Score (1-5)]]>=4,"Satisfied",TicketsTable[[#This Row],[CSAT_Score (1-5)]]>=1,"Unsatisfied",ISBLANK(TicketsTable[[#This Row],[CSAT_Score (1-5)]]),"X")} -> Satisfied | L7: {=IFERROR(_xlfn.IFS(OR(TicketsTable[[#This Row],[CES_Score (1-7)]]=1,TicketsTable[[#This Row],[CES_Score (1-7)]]=2,TicketsTable[[#This Row],[CES_Score (1-7)]]=3),"High Effort",OR(TicketsTable[[#This Row],[CES_Score (1-7)]]=6,TicketsTable[[#This Row],[CES_Score (1-7)]]=7),"Low Effort",OR(TicketsTable[[#This Row],[CES_Score (1-7)]]=4,TicketsTable[[#This Row],[CES_Score (1-7)]]=5),"Neutral"),"No Response")} -> Low Effort | N7: =P7 -> Consumer | O7: =Q7 -> 0.63087248 | P7: Consumer | Q7: 0.63087248 | R7: 0.36912752 | S7: 1 | U7: Asia Pacific | V7: 0.56435644 | W7: 0.43564356 | X7: 1 | Z7: =V7 -> 0.56435644
A8: TCK-20503 | B8: 46025 | C8: CUST-1090 | D8: Email | E8: Liu Wei | F8: Account Access | G8: No | H8: 39.2 | I8: 3 | J8: 2 | K8: {=_xlfn.IFS(TicketsTable[[#This Row],[CSAT_Score (1-5)]]>=4,"Satisfied",TicketsTable[[#This Row],[CSAT_Score (1-5)]]>=1,"Unsatisfied",ISBLANK(TicketsTable[[#This Row],[CSAT_Score (1-5)]]),"X")} -> Unsatisfied | L8: {=IFERROR(_xlfn.IFS(OR(TicketsTable[[#This Row],[CES_Score (1-7)]]=1,TicketsTable[[#This Row],[CES_Score (1-7)]]=2,TicketsTable[[#This Row],[CES_Score (1-7)]]=3),"High Effort",OR(TicketsTable[[#This Row],[CES_Score (1-7)]]=6,TicketsTable[[#This Row],[CES_Score (1-7)]]=7),"Low Effort",OR(TicketsTable[[#This Row],[CES_Score (1-7)]]=4,TicketsTable[[#This Row],[CES_Score (1-7)]]=5),"Neutral"),"No Response")} -> High Effort | N8: =P8 -> Small Business | O8: =Q8 -> 0.60204082 | P8: Small Business | Q8: 0.60204082 | R8: 0.39795918 | S8: 1 | U8: Europe | V8: 0.66371681 | W8: 0.33628319 | X8: 1 | Z8: =V8 -> 0.66371681
A9: TCK-20622 | B9: 46025 | C9: CUST-1034 | D9: Live Chat | E9: James Okafor | F9: Billing Issue | G9: Yes | H9: 1.6 | I9: 4 | K9: {=_xlfn.IFS(TicketsTable[[#This Row],[CSAT_Score (1-5)]]>=4,"Satisfied",TicketsTable[[#This Row],[CSAT_Score (1-5)]]>=1,"Unsatisfied",ISBLANK(TicketsTable[[#This Row],[CSAT_Score (1-5)]]),"X")} -> Satisfied | L9: {=IFERROR(_xlfn.IFS(OR(TicketsTable[[#This Row],[CES_Score (1-7)]]=1,TicketsTable[[#This Row],[CES_Score (1-7)]]=2,TicketsTable[[#This Row],[CES_Score (1-7)]]=3),"High Effort",OR(TicketsTable[[#This Row],[CES_Score (1-7)]]=6,TicketsTable[[#This Row],[CES_Score (1-7)]]=7),"Low Effort",OR(TicketsTable[[#This Row],[CES_Score (1-7)]]=4,TicketsTable[[#This Row],[CES_Score (1-7)]]=5),"Neutral"),"No Response")} -> No Response | P9: Grand Total | Q9: 0.62373737 | R9: 0.37626263 | S9: 1 | U9: Latin America | V9: 0.62105263 | W9: 0.37894737 | X9: 1 | Z9: =V9 -> 0.62105263
A10: TCK-20521 | B10: 46026 | C10: CUST-1062 | D10: Social Media | E10: Priya Nair | F10: Product Defect | G10: No | H10: 20.8 | I10: 1 | J10: 1 | K10: {=_xlfn.IFS(TicketsTable[[#This Row],[CSAT_Score (1-5)]]>=4,"Satisfied",TicketsTable[[#This Row],[CSAT_Score (1-5)]]>=1,"Unsatisfied",ISBLANK(TicketsTable[[#This Row],[CSAT_Score (1-5)]]),"X")} -> Unsatisfied | L10: {=IFERROR(_xlfn.IFS(OR(TicketsTable[[#This Row],[CES_Score (1-7)]]=1,TicketsTable[[#This Row],[CES_Score (1-7)]]=2,TicketsTable[[#This Row],[CES_Score (1-7)]]=3),"High Effort",OR(TicketsTable[[#This Row],[CES_Score (1-7)]]=6,TicketsTable[[#This Row],[CES_Score (1-7)]]=7),"Low Effort",OR(TicketsTable[[#This Row],[CES_Score (1-7)]]=4,TicketsTable[[#This Row],[CES_Score (1-7)]]=5),"Neutral"),"No Response")} -> High Effort | U10: North America | V10: 0.64367816 | W10: 0.35632184 | X10: 1 | Z10: =V10 -> 0.64367816
A11: TCK-20289 | B11: 46027 | C11: CUST-1133 | D11: Email | E11: Nadia Petrov | F11: Return/Refund | G11: Yes | H11: 0.8 | I11: 4 | J11: 6 | K11: {=_xlfn.IFS(TicketsTable[[#This Row],[CSAT_Score (1-5)]]>=4,"Satisfied",TicketsTable[[#This Row],[CSAT_Score (1-5)]]>=1,"Unsatisfied",ISBLANK(TicketsTable[[#This Row],[CSAT_Score (1-5)]]),"X")} -> Satisfied | L11: {=IFERROR(_xlfn.IFS(OR(TicketsTable[[#This Row],[CES_Score (1-7)]]=1,TicketsTable[[#This Row],[CES_Score (1-7)]]=2,TicketsTable[[#This Row],[CES_Score (1-7)]]=3),"High Effort",OR(TicketsTable[[#This Row],[CES_Score (1-7)]]=6,TicketsTable[[#This Row],[CES_Score (1-7)]]=7),"Low Effort",OR(TicketsTable[[#This Row],[CES_Score (1-7)]]=4,TicketsTable[[#This Row],[CES_Score (1-7)]]=5),"Neutral"),"No Response")} -> Low Effort | P11: Count of CSAT Status | Q11: Column Labels | U11: Grand Total | V11: 0.62373737 | W11: 0.37626263 | X11: 1
A12: TCK-20405 | B12: 46029 | C12: CUST-1254 | D12: Social Media | E12: Tom Becker | F12: Technical Support | G12: Yes | H12: 3.3 | I12: 5 | J12: 5 | K12: {=_xlfn.IFS(TicketsTable[[#This Row],[CSAT_Score (1-5)]]>=4,"Satisfied",TicketsTable[[#This Row],[CSAT_Score (1-5)]]>=1,"Unsatisfied",ISBLANK(TicketsTable[[#This Row],[CSAT_Score (1-5)]]),"X")} -> Satisfied | L12: {=IFERROR(_xlfn.IFS(OR(TicketsTable[[#This Row],[CES_Score (1-7)]]=1,TicketsTable[[#This Row],[CES_Score (1-7)]]=2,TicketsTable[[#This Row],[CES_Score (1-7)]]=3),"High Effort",OR(TicketsTable[[#This Row],[CES_Score (1-7)]]=6,TicketsTable[[#This Row],[CES_Score (1-7)]]=7),"Low Effort",OR(TicketsTable[[#This Row],[CES_Score (1-7)]]=4,TicketsTable[[#This Row],[CES_Score (1-7)]]=5),"Neutral"),"No Response")} -> Neutral | P12: Row Labels | Q12: Satisfied | R12: Unsatisfied | S12: Grand Total
A13: TCK-20669 | B13: 46029 | C13: CUST-1205 | D13: Email | E13: Priya Nair | F13: Billing Issue | G13: Yes | H13: 0.3 | I13: 5 | J13: 7 | K13: {=_xlfn.IFS(TicketsTable[[#This Row],[CSAT_Score (1-5)]]>=4,"Satisfied",TicketsTable[[#This Row],[CSAT_Score (1-5)]]>=1,"Unsatisfied",ISBLANK(TicketsTable[[#This Row],[CSAT_Score (1-5)]]),"X")} -> Satisfied | L13: {=IFERROR(_xlfn.IFS(OR(TicketsTable[[#This Row],[CES_Score (1-7)]]=1,TicketsTable[[#This Row],[CES_Score (1-7)]]=2,TicketsTable[[#This Row],[CES_Score (1-7)]]=3),"High Effort",OR(TicketsTable[[#This Row],[CES_Score (1-7)]]=6,TicketsTable[[#This Row],[CES_Score (1-7)]]=7),"Low Effort",OR(TicketsTable[[#This Row],[CES_Score (1-7)]]=4,TicketsTable[[#This Row],[CES_Score (1-7)]]=5),"Neutral"),"No Response")} -> Low Effort | N13: =P13 -> Email | O13: =Q13 -> 0.56122449 | P13: Email | Q13: 0.56122449 | R13: 0.43877551 | S13: 1 | U13: Count of CSAT Status | V13: Column Labels
A14: TCK-20493 | B14: 46030 | C14: CUST-1246 | D14: Live Chat | E14: James Okafor | F14: Product Defect | G14: Yes | H14: 1.1 | I14: 5 | J14: 5 | K14: {=_xlfn.IFS(TicketsTable[[#This Row],[CSAT_Score (1-5)]]>=4,"Satisfied",TicketsTable[[#This Row],[CSAT_Score (1-5)]]>=1,"Unsatisfied",ISBLANK(TicketsTable[[#This Row],[CSAT_Score (1-5)]]),"X")} -> Satisfied | L14: {=IFERROR(_xlfn.IFS(OR(TicketsTable[[#This Row],[CES_Score (1-7)]]=1,TicketsTable[[#This Row],[CES_Score (1-7)]]=2,TicketsTable[[#This Row],[CES_Score (1-7)]]=3),"High Effort",OR(TicketsTable[[#This Row],[CES_Score (1-7)]]=6,TicketsTable[[#This Row],[CES_Score (1-7)]]=7),"Low Effort",OR(TicketsTable[[#This Row],[CES_Score (1-7)]]=4,TicketsTable[[#This Row],[CES_Score (1-7)]]=5),"Neutral"),"No Response")} -> Neutral | N14: =P14 -> Live Chat | O14: =Q14 -> 0.68361582 | P14: Live Chat | Q14: 0.68361582 | R14: 0.31638418 | S14: 1 | U14: Row Labels | V14: Satisfied | W14: Unsatisfied | X14: Grand Total
A15: TCK-20677 | B15: 46030 | C15: CUST-1061 | D15: Phone | E15: Grace Kim | F15: Account Access | G15: Yes | H15: 3.4 | I15: 5 | J15: 6 | K15: {=_xlfn.IFS(TicketsTable[[#This Row],[CSAT_Score (1-5)]]>=4,"Satisfied",TicketsTable[[#This Row],[CSAT_Score (1-5)]]>=1,"Unsatisfied",ISBLANK(TicketsTable[[#This Row],[CSAT_Score (1-5)]]),"X")} -> Satisfied | L15: {=IFERROR(_xlfn.IFS(OR(TicketsTable[[#This Row],[CES_Score (1-7)]]=1,TicketsTable[[#This Row],[CES_Score (1-7)]]=2,TicketsTable[[#This Row],[CES_Score (1-7)]]=3),"High Effort",OR(TicketsTable[[#This Row],[CES_Score (1-7)]]=6,TicketsTable[[#This Row],[CES_Score (1-7)]]=7),"Low Effort",OR(TicketsTable[[#This Row],[CES_Score (1-7)]]=4,TicketsTable[[#This Row],[CES_Score (1-7)]]=5),"Neutral"),"No Response")} -> Low Effort | N15: =P15 -> Phone | O15: =Q15 -> 0.67058824 | P15: Phone | Q15: 0.67058824 | R15: 0.32941176 | S15: 1 | U15: Active | V15: 0.62280702 | W15: 0.37719298 | X15: 1
A16: TCK-20520 | B16: 46031 | C16: CUST-1169 | D16: Live Chat | E16: Liu Wei | F16: Order Delay | G16: Yes | H16: 0.4 | I16: 4 | J16: 7 | K16: {=_xlfn.IFS(TicketsTable[[#This Row],[CSAT_Score (1-5)]]>=4,"Satisfied",TicketsTable[[#This Row],[CSAT_Score (1-5)]]>=1,"Unsatisfied",ISBLANK(TicketsTable[[#This Row],[CSAT_Score (1-5)]]),"X")} -> Satisfied | L16: {=IFERROR(_xlfn.IFS(OR(TicketsTable[[#This Row],[CES_Score (1-7)]]=1,TicketsTable[[#This Row],[CES_Score (1-7)]]=2,TicketsTable[[#This Row],[CES_Score (1-7)]]=3),"High Effort",OR(TicketsTable[[#This Row],[CES_Score (1-7)]]=6,TicketsTable[[#This Row],[CES_Score (1-7)]]=7),"Low Effort",OR(TicketsTable[[#This Row],[CES_Score (1-7)]]=4,TicketsTable[[#This Row],[CES_Score (1-7)]]=5),"Neutral"),"No Response")} -> Low Effort | N16: =P16 -> Social Media | O16: =Q16 -> 0.38888889 | P16: Social Media | Q16: 0.38888889 | R16: 0.61111111 | S16: 1 | U16: Churned | V16: 0.62962963 | W16: 0.37037037 | X16: 1
A17: TCK-20666 | B17: 46031 | C17: CUST-1162 | D17: Social Media | E17: Liu Wei | F17: Product Defect | G17: Yes | H17: 0.8 | I17: 5 | J17: 6 | K17: {=_xlfn.IFS(TicketsTable[[#This Row],[CSAT_Score (1-5)]]>=4,"Satisfied",TicketsTable[[#This Row],[CSAT_Score (1-5)]]>=1,"Unsatisfied",ISBLANK(TicketsTable[[#This Row],[CSAT_Score (1-5)]]),"X")} -> Satisfied | L17: {=IFERROR(_xlfn.IFS(OR(TicketsTable[[#This Row],[CES_Score (1-7)]]=1,TicketsTable[[#This Row],[CES_Score (1-7)]]=2,TicketsTable[[#This Row],[CES_Score (1-7)]]=3),"High Effort",OR(TicketsTable[[#This Row],[CES_Score (1-7)]]=6,TicketsTable[[#This Row],[CES_Score (1-7)]]=7),"Low Effort",OR(TicketsTable[[#This Row],[CES_Score (1-7)]]=4,TicketsTable[[#This Row],[CES_Score (1-7)]]=5),"Neutral"),"No Response")} -> Low Effort | P17: Grand Total | Q17: 0.62373737 | R17: 0.37626263 | S17: 1 | U17: Grand Total | V17: 0.62373737 | W17: 0.37626263 | X17: 1
A18: TCK-20699 | B18: 46031 | C18: CUST-1220 | D18: Phone | E18: James Okafor | F18: Product Defect | G18: Yes | H18: 1.8 | I18: 3 | J18: 7 | K18: {=_xlfn.IFS(TicketsTable[[#This Row],[CSAT_Score (1-5)]]>=4,"Satisfied",TicketsTable[[#This Row],[CSAT_Score (1-5)]]>=1,"Unsatisfied",ISBLANK(TicketsTable[[#This Row],[CSAT_Score (1-5)]]),"X")} -> Unsatisfied | L18: {=IFERROR(_xlfn.IFS(OR(TicketsTable[[#This Row],[CES_Score (1-7)]]=1,TicketsTable[[#This Row],[CES_Score (1-7)]]=2,TicketsTable[[#This Row],[CES_Score (1-7)]]=3),"High Effort",OR(TicketsTable[[#This Row],[CES_Score (1-7)]]=6,TicketsTable[[#This Row],[CES_Score (1-7)]]=7),"Low Effort",OR(TicketsTable[[#This Row],[CES_Score (1-7)]]=4,TicketsTable[[#This Row],[CES_Score (1-7)]]=5),"Neutral"),"No Response")} -> Low Effort
A19: TCK-20373 | B19: 46032 | C19: CUST-1046 | D19: Live Chat | E19: Nadia Petrov | F19: Order Delay | G19: Yes | H19: 0.1 | I19: 4 | K19: {=_xlfn.IFS(TicketsTable[[#This Row],[CSAT_Score (1-5)]]>=4,"Satisfied",TicketsTable[[#This Row],[CSAT_Score (1-5)]]>=1,"Unsatisfied",ISBLANK(TicketsTable[[#This Row],[CSAT_Score (1-5)]]),"X")} -> Satisfied | L19: {=IFERROR(_xlfn.IFS(OR(TicketsTable[[#This Row],[CES_Score (1-7)]]=1,TicketsTable[[#This Row],[CES_Score (1-7)]]=2,TicketsTable[[#This Row],[CES_Score (1-7)]]=3),"High Effort",OR(TicketsTable[[#This Row],[CES_Score (1-7)]]=6,TicketsTable[[#This Row],[CES_Score (1-7)]]=7),"Low Effort",OR(TicketsTable[[#This Row],[CES_Score (1-7)]]=4,TicketsTable[[#This Row],[CES_Score (1-7)]]=5),"Neutral"),"No Response")} -> No Response | P19: Count of CSAT Status | Q19: Column Labels
A20: TCK-20641 | B20: 46032 | C20: CUST-1092 | D20: Phone | E20: Nadia Petrov | F20: Account Access | G20: Yes | H20: 3.5 | I20: 3 | J20: 4 | K20: {=_xlfn.IFS(TicketsTable[[#This Row],[CSAT_Score (1-5)]]>=4,"Satisfied",TicketsTable[[#This Row],[CSAT_Score (1-5)]]>=1,"Unsatisfied",ISBLANK(TicketsTable[[#This Row],[CSAT_Score (1-5)]]),"X")} -> Unsatisfied | L20: {=IFERROR(_xlfn.IFS(OR(TicketsTable[[#This Row],[CES_Score (1-7)]]=1,TicketsTable[[#This Row],[CES_Score (1-7)]]=2,TicketsTable[[#This Row],[CES_Score (1-7)]]=3),"High Effort",OR(TicketsTable[[#This Row],[CES_Score (1-7)]]=6,TicketsTable[[#This Row],[CES_Score (1-7)]]=7),"Low Effort",OR(TicketsTable[[#This Row],[CES_Score (1-7)]]=4,TicketsTable[[#This Row],[CES_Score (1-7)]]=5),"Neutral"),"No Response")} -> Neutral | P20: Row Labels | Q20: Satisfied | R20: Unsatisfied | S20: Grand Total | U20: Count of CSAT Status | V20: Column Labels
A21: TCK-20447 | B21: 46033 | C21: CUST-1078 | D21: Social Media | E21: Nadia Petrov | F21: Order Delay | G21: No | H21: 45.9 | I21: 2 | J21: 2 | K21: {=_xlfn.IFS(TicketsTable[[#This Row],[CSAT_Score (1-5)]]>=4,"Satisfied",TicketsTable[[#This Row],[CSAT_Score (1-5)]]>=1,"Unsatisfied",ISBLANK(TicketsTable[[#This Row],[CSAT_Score (1-5)]]),"X")} -> Unsatisfied | L21: {=IFERROR(_xlfn.IFS(OR(TicketsTable[[#This Row],[CES_Score (1-7)]]=1,TicketsTable[[#This Row],[CES_Score (1-7)]]=2,TicketsTable[[#This Row],[CES_Score (1-7)]]=3),"High Effort",OR(TicketsTable[[#This Row],[CES_Score (1-7)]]=6,TicketsTable[[#This Row],[CES_Score (1-7)]]=7),"Low Effort",OR(TicketsTable[[#This Row],[CES_Score (1-7)]]=4,TicketsTable[[#This Row],[CES_Score (1-7)]]=5),"Neutral"),"No Response")} -> High Effort | N21: =P21 -> Ahmed Hassan | O21: =Q21 -> 0.64 | P21: Ahmed Hassan | Q21: 0.64 | R21: 0.36 | S21: 1 | U21: Row Labels | V21: Satisfied | W21: Unsatisfied | X21: Grand Total
A22: TCK-20469 | B22: 46033 | C22: CUST-1112 | D22: Phone | E22: Priya Nair | F22: Order Delay | G22: Yes | H22: 0.3 | I22: 5 | J22: 6 | K22: {=_xlfn.IFS(TicketsTable[[#This Row],[CSAT_Score (1-5)]]>=4,"Satisfied",TicketsTable[[#This Row],[CSAT_Score (1-5)]]>=1,"Unsatisfied",ISBLANK(TicketsTable[[#This Row],[CSAT_Score (1-5)]]),"X")} -> Satisfied | L22: {=IFERROR(_xlfn.IFS(OR(TicketsTable[[#This Row],[CES_Score (1-7)]]=1,TicketsTable[[#This Row],[CES_Score (1-7)]]=2,TicketsTable[[#This Row],[CES_Score (1-7)]]=3),"High Effort",OR(TicketsTable[[#This Row],[CES_Score (1-7)]]=6,TicketsTable[[#This Row],[CES_Score (1-7)]]=7),"Low Effort",OR(TicketsTable[[#This Row],[CES_Score (1-7)]]=4,TicketsTable[[#This Row],[CES_Score (1-7)]]=5),"Neutral"),"No Response")} -> Low Effort | N22: =P22 -> Daniel Ortiz | O22: =Q22 -> 0.575 | P22: Daniel Ortiz | Q22: 0.575 | R22: 0.425 | S22: 1 | U22: Jan | V22: 0.55769231 | W22: 0.44230769 | X22: 1 | Y22: =U22 -> Jan | Z22: =V22 -> 0.55769231
A23: TCK-20739 | B23: 46033 | C23: CUST-1226 | D23: Live Chat | E23: Daniel Ortiz | F23: Billing Issue | G23: Yes | H23: 3.8 | I23: 3 | K23: {=_xlfn.IFS(TicketsTable[[#This Row],[CSAT_Score (1-5)]]>=4,"Satisfied",TicketsTable[[#This Row],[CSAT_Score (1-5)]]>=1,"Unsatisfied",ISBLANK(TicketsTable[[#This Row],[CSAT_Score (1-5)]]),"X")} -> Unsatisfied | L23: {=IFERROR(_xlfn.IFS(OR(TicketsTable[[#This Row],[CES_Score (1-7)]]=1,TicketsTable[[#This Row],[CES_Score (1-7)]]=2,TicketsTable[[#This Row],[CES_Score (1-7)]]=3),"High Effort",OR(TicketsTable[[#This Row],[CES_Score (1-7)]]=6,TicketsTable[[#This Row],[CES_Score (1-7)]]=7),"Low Effort",OR(TicketsTable[[#This Row],[CES_Score (1-7)]]=4,TicketsTable[[#This Row],[CES_Score (1-7)]]=5),"Neutral"),"No Response")} -> No Response | N23: =P23 -> Grace Kim | O23: =Q23 -> 0.57142857 | P23: Grace Kim | Q23: 0.57142857 | R23: 0.42857143 | S23: 1 | U23: Feb | V23: 0.55 | W23: 0.45 | X23: 1 | Y23: =U23 -> Feb | Z23: =V23 -> 0.55
A24: TCK-20423 | B24: 46034 | C24: CUST-1004 | D24: Phone | E24: Liu Wei | F24: Product Defect | G24: No | H24: 68.9 | I24: 3 | J24: 2 | K24: {=_xlfn.IFS(TicketsTable[[#This Row],[CSAT_Score (1-5)]]>=4,"Satisfied",TicketsTable[[#This Row],[CSAT_Score (1-5)]]>=1,"Unsatisfied",ISBLANK(TicketsTable[[#This Row],[CSAT_Score (1-5)]]),"X")} -> Unsatisfied | L24: {=IFERROR(_xlfn.IFS(OR(TicketsTable[[#This Row],[CES_Score (1-7)]]=1,TicketsTable[[#This Row],[CES_Score (1-7)]]=2,TicketsTable[[#This Row],[CES_Score (1-7)]]=3),"High Effort",OR(TicketsTable[[#This Row],[CES_Score (1-7)]]=6,TicketsTable[[#This Row],[CES_Score (1-7)]]=7),"Low Effort",OR(TicketsTable[[#This Row],[CES_Score (1-7)]]=4,TicketsTable[[#This Row],[CES_Score (1-7)]]=5),"Neutral"),"No Response")} -> High Effort | N24: =P24 -> James Okafor | O24: =Q24 -> 0.61111111 | P24: James Okafor | Q24: 0.61111111 | R24: 0.38888889 | S24: 1 | U24: Mar | V24: 0.64473684 | W24: 0.35526316 | X24: 1 | Y24: =U24 -> Mar | Z24: =V24 -> 0.64473684
A25: TCK-20480 | B25: 46034 | C25: CUST-1219 | D25: Live Chat | E25: Grace Kim | F25: Technical Support | G25: Yes | H25: 2.7 | I25: 5 | J25: 4 | K25: {=_xlfn.IFS(TicketsTable[[#This Row],[CSAT_Score (1-5)]]>=4,"Satisfied",TicketsTable[[#This Row],[CSAT_Score (1-5)]]>=1,"Unsatisfied",ISBLANK(TicketsTable[[#This Row],[CSAT_Score (1-5)]]),"X")} -> Satisfied | L25: {=IFERROR(_xlfn.IFS(OR(TicketsTable[[#This Row],[CES_Score (1-7)]]=1,TicketsTable[[#This Row],[CES_Score (1-7)]]=2,TicketsTable[[#This Row],[CES_Score (1-7)]]=3),"High Effort",OR(TicketsTable[[#This Row],[CES_Score (1-7)]]=6,TicketsTable[[#This Row],[CES_Score (1-7)]]=7),"Low Effort",OR(TicketsTable[[#This Row],[CES_Score (1-7)]]=4,TicketsTable[[#This Row],[CES_Score (1-7)]]=5),"Neutral"),"No Response")} -> Neutral | N25: =P25 -> Liu Wei | O25: =Q25 -> 0.63461538 | P25: Liu Wei | Q25: 0.63461538 | R25: 0.36538462 | S25: 1 | U25: Apr | V25: 0.734375 | W25: 0.265625 | X25: 1 | Y25: =U25 -> Apr | Z25: =V25 -> 0.734375
A26: TCK-20638 | B26: 46034 | C26: CUST-1088 | D26: Live Chat | E26: James Okafor | F26: Product Defect | G26: Yes | H26: 0.8 | I26: 4 | J26: 6 | K26: {=_xlfn.IFS(TicketsTable[[#This Row],[CSAT_Score (1-5)]]>=4,"Satisfied",TicketsTable[[#This Row],[CSAT_Score (1-5)]]>=1,"Unsatisfied",ISBLANK(TicketsTable[[#This Row],[CSAT_Score (1-5)]]),"X")} -> Satisfied | L26: {=IFERROR(_xlfn.IFS(OR(TicketsTable[[#This Row],[CES_Score (1-7)]]=1,TicketsTable[[#This Row],[CES_Score (1-7)]]=2,TicketsTable[[#This Row],[CES_Score (1-7)]]=3),"High Effort",OR(TicketsTable[[#This Row],[CES_Score (1-7)]]=6,TicketsTable[[#This Row],[CES_Score (1-7)]]=7),"Low Effort",OR(TicketsTable[[#This Row],[CES_Score (1-7)]]=4,TicketsTable[[#This Row],[CES_Score (1-7)]]=5),"Neutral"),"No Response")} -> Low Effort | N26: =P26 -> Maria Santos | O26: =Q26 -> 0.51851852 | P26: Maria Santos | Q26: 0.51851852 | R26: 0.48148148 | S26: 1 | U26: May | V26: 0.65333333 | W26: 0.34666667 | X26: 1 | Y26: =U26 -> May | Z26: =V26 -> 0.65333333
